Workbook

Sheet Dashboard
A1: Deloitte.
B4: FDE Recruiting Dashboard | J4: Report Date
J5: =TODAY() -> 46146
B7: ACTIVE CANDIDATES | E7: IN INTERVIEW LOOP | H7: OFFERS OUT | K7: HIRED
B8: =COUNTIF('Candidate Tracker'!$Z$8:$Z$256,"Active") -> 63 | E8: =COUNTIF('Candidate Tracker'!$Y$8:$Y$256,"Round 1 - Invite")+COUNTIF('Candidate Tracker'!$Y$8:$Y$256,"Round 1 - Conducted")+COUNTIF('Candidate Tracker'!$Y$8:$Y$256,"Round 2 - Invite")+COUNTIF('Candidate Tracker'!$Y$8:$Y$256,"Round 2 - Conducted")+COUNTIF('Candidate Tracker'!$Y$8:$Y$256,"Round 3 - Invite")+COUNTIF('Candidate Tracker'!$Y$8:$Y$256,"Round 3 - Conducted") -> 29 | H8: =COUNTIF('Candidate Tracker'!$Y$8:$Y$256,"Offer Extended") -> 0 | K8: =COUNTIF('Candidate Tracker'!$Y$8:$Y$256,"Hired and Ready to Onboard") -> 1
B9: ="of "&COUNTA('Candidate Tracker'!$C$8:$C$256)&" total in tracker" -> of 65 total in tracker | E9: "R1 + R2 + R3 in flight" | H9: "awaiting acceptance" | K9: "to date"
B11: PIPELINE FUNNEL — CANDIDATES BY STAGE | H11: INTERVIEWER CAPACITY vs DEMAND
B12: Stage | E12: Invite / Scheduled | F12: Conducted | G12: Total | H12: Round | J12: Demand (in queue) | K12: Weekly Capacity | L12: Load (weeks) | M12: Status
B13: Total Applicants | G13: =COUNTA('Candidate Tracker'!$C$8:$C$256) -> 65 | H13: Recruiter Screen | J13: =COUNTIF('Candidate Tracker'!$Y$8:$Y$256,"Recruiter Screen - Being Scheduled")+COUNTIF('Candidate Tracker'!$Y$8:$Y$256,"Recruiter Screen - Invited") -> 27 | K13: ='Interviewer Capacity'!$E$9 -> 40 | L13: =IFERROR(J13/K13,0) -> 0.675 | M13: =IF(K13=0,"⚠ NO CAPACITY",IF(L13>=2,"⚠ AT RISK",IF(L13>=1,"Watch","On Track"))) -> On Track
B14: Recruiter Screen | E14: =COUNTIF('Candidate Tracker'!$Y$8:$Y$256,"Recruiter Screen - Being Scheduled")+COUNTIF('Candidate Tracker'!$Y$8:$Y$256,"Recruiter Screen - Invited") -> 27 | F14: =COUNTIF('Candidate Tracker'!$Y$8:$Y$256,"Recruiter Screen - Conducted") -> 7 | G14: =E14+F14 -> 34 | H14: Round 1 (R1) | J14: =E15 -> 15 | K14: ='Interviewer Capacity'!$E$10 -> 26 | L14: =IFERROR(J14/K14,0) -> 0.57692308 | M14: =IF(K14=0,"⚠ NO CAPACITY",IF(L14>=2,"⚠ AT RISK",IF(L14>=1,"Watch","On Track"))) -> On Track
B15: Round 1 — Behavioral Screening | E15: =COUNTIF('Candidate Tracker'!$Y$8:$Y$256,"Round 1 - Invite") -> 15 | F15: =COUNTIF('Candidate Tracker'!$Y$8:$Y$256,"Round 1 - Conducted") -> 5 | G15: =E15+F15 -> 20 | H15: Round 2 (R2) | J15: =E16 -> 8 | K15: ='Interviewer Capacity'!$E$11 -> 29 | L15: =IFERROR(J15/K15,0) -> 0.27586207 | M15: =IF(K15=0,"⚠ NO CAPACITY",IF(L15>=2,"⚠ AT RISK",IF(L15>=1,"Watch","On Track"))) -> On Track
B16: Round 2 — Panel Interview | E16: =COUNTIF('Candidate Tracker'!$Y$8:$Y$256,"Round 2 - Invite") -> 8 | F16: =COUNTIF('Candidate Tracker'!$Y$8:$Y$256,"Round 2 - Conducted") -> 0 | G16: =E16+F16 -> 8 | H16: Round 3 (R3) | J16: =E17 -> 1 | K16: ='Interviewer Capacity'!$E$12 -> 8 | L16: =IFERROR(J16/K16,0) -> 0.125 | M16: =IF(K16=0,"⚠ NO CAPACITY",IF(L16>=2,"⚠ AT RISK",IF(L16>=1,"Watch","On Track"))) -> On Track
B17: Round 3 — Final 1:1 Interview | E17: =COUNTIF('Candidate Tracker'!$Y$8:$Y$256,"Round 3 - Invite") -> 1 | F17: =COUNTIF('Candidate Tracker'!$Y$8:$Y$256,"Round 3 - Conducted") -> 0 | G17: =E17+F17 -> 1 | H17: Load = candidates in queue ÷ weekly interview capacity. ≥ 2 weeks = AT RISK. Edit capacity inputs on the 'Interviewer Capacity' sheet.
B18: Offer Extended | F18: =COUNTIF('Candidate Tracker'!$Y$8:$Y$256,"Offer Extended") -> 0 | G18: =F18 -> 0
B19: Hired and Ready to Onboard | F19: =COUNTIF('Candidate Tracker'!$Y$8:$Y$256,"Hired and Ready to Onboard") -> 1 | G19: =F19 -> 1
B22: VOLUME PROJECTION — WHAT HAPPENS IF CANDIDATE FLOW INCREASES?
B23: Editable assumptions (yellow):
B24: Recruiter screens / week | C24: 40 | E24: Stage | H24: Weekly Demand (projected) | I24: Weekly Capacity | J24: Gap | K24: Status
B25: Screen → R1 pass rate | C25: 0.5 | E25: Recruiter Screen | H25: =$C$24 -> 40 | I25: ='Interviewer Capacity'!$E$9 -> 40 | J25: =I25-H25 -> 0 | K25: =IF(I25=0,"⚠ NO CAPACITY",IF(H25>I25,"⚠ UNDERCAPACITY by "&TEXT(H25-I25,"0.0")&"/wk",IF(H25/I25>=0.8,"Near limit ("&TEXT(H25/I25,"0%")&" util.)","OK ("&TEXT(H25/I25,"0%")&" util.)"))) -> Near limit (100% util.)
B26: R1 → R2 pass rate | C26: 0.4 | E26: Round 1 | H26: =$C$24*$C$25 -> 20 | I26: ='Interviewer Capacity'!$E$10 -> 26 | J26: =I26-H26 -> 6 | K26: =IF(I26=0,"⚠ NO CAPACITY",IF(H26>I26,"⚠ UNDERCAPACITY by "&TEXT(H26-I26,"0.0")&"/wk",IF(H26/I26>=0.8,"Near limit ("&TEXT(H26/I26,"0%")&" util.)","OK ("&TEXT(H26/I26,"0%")&" util.)"))) -> OK (77% util.)
B27: R2 → R3 pass rate | C27: 0.5 | E27: Round 2 | H27: =$C$24*$C$25*$C$26 -> 8 | I27: ='Interviewer Capacity'!$E$11 -> 29 | J27: =I27-H27 -> 21 | K27: =IF(I27=0,"⚠ NO CAPACITY",IF(H27>I27,"⚠ UNDERCAPACITY by "&TEXT(H27-I27,"0.0")&"/wk",IF(H27/I27>=0.8,"Near limit ("&TEXT(H27/I27,"0%")&" util.)","OK ("&TEXT(H27/I27,"0%")&" util.)"))) -> OK (28% util.)
B28: R3 → Offer rate | C28: 0.7 | E28: Round 3 | H28: =$C$24*$C$25*$C$26*$C$27 -> 4 | I28: ='Interviewer Capacity'!$E$12 -> 8 | J28: =I28-H28 -> 4 | K28: =IF(I28=0,"⚠ NO CAPACITY",IF(H28>I28,"⚠ UNDERCAPACITY by "&TEXT(H28-I28,"0.0")&"/wk",IF(H28/I28>=0.8,"Near limit ("&TEXT(H28/I28,"0%")&" util.)","OK ("&TEXT(H28/I28,"0%")&" util.)"))) -> OK (50% util.)
B31: DAYS IN QUEUE — HOW LONG ARE CANDIDATES WAITING?
B32: Days since last touchpoint, by stage. N/A excluded. Targets: <7 OK, 7-14 watch, 15+ at risk.
B33: Stage | C33: Active in queue | D33: Avg days waiting | E33: Max days waiting | F33: # > 14 days | G33: Status
B34: Recruiter Screen | C34: =COUNT('Candidate Tracker'!H8:H256) -> 0 | D34: =IFERROR(AVERAGE('Candidate Tracker'!H8:H256),0) -> 0 | E34: =IFERROR(MAX('Candidate Tracker'!H8:H256),0) -> 0 | F34: =COUNTIF('Candidate Tracker'!H8:H256,">14") -> 0 | G34: =IF(C34=0,"—",IF(E34>=15,"⚠ At Risk",IF(E34>=7,"Watch","OK"))) -> —
B35: Round 1 | C35: =COUNT('Candidate Tracker'!K8:K256) -> 0 | D35: =IFERROR(AVERAGE('Candidate Tracker'!K8:K256),0) -> 0 | E35: =IFERROR(MAX('Candidate Tracker'!K8:K256),0) -> 0 | F35: =COUNTIF('Candidate Tracker'!K8:K256,">14") -> 0 | G35: =IF(C35=0,"—",IF(E35>=15,"⚠ At Risk",IF(E35>=7,"Watch","OK"))) -> —
B36: Round 2 | C36: =COUNT('Candidate Tracker'!O8:O256) -> 20 | D36: =IFERROR(AVERAGE('Candidate Tracker'!O8:O256),0) -> 7.4 | E36: =IFERROR(MAX('Candidate Tracker'!O8:O256),0) -> 17 | F36: =COUNTIF('Candidate Tracker'!O8:O256,">14") -> 2 | G36: =IF(C36=0,"—",IF(E36>=15,"⚠ At Risk",IF(E36>=7,"Watch","OK"))) -> ⚠ At Risk
B37: Round 3 | C37: =COUNT('Candidate Tracker'!U8:U256) -> 5 | D37: =IFERROR(AVERAGE('Candidate Tracker'!U8:U256),0) -> 5.8 | E37: =IFERROR(MAX('Candidate Tracker'!U8:U256),0) -> 14 | F37: =COUNTIF('Candidate Tracker'!U8:U256,">14") -> 0 | G37: =IF(C37=0,"—",IF(E37>=15,"⚠ At Risk",IF(E37>=7,"Watch","OK"))) -> Watch
B38: Longest wait: | C38: =INDEX(B34:B37,MATCH(MAX(E34:E37),E34:E37,0))&" — "&MAX(E34:E37)&" days" -> Round 2 — 17 days
B40: KEY MESSAGE
B41: ="As of "&TEXT(TODAY(),"mmmm d")&", "&COUNTIF('Candidate Tracker'!$Z$8:$Z$256,"Active")&" candidate"&IF(COUNTIF('Candidate Tracker'!$Z$8:$Z$256,"Active")=1,"","s")&" "&IF(COUNTIF('Candidate Tracker'!$Z$8:$Z$256,"Active")=1,"is","are")&" active in the FDE pipeline. "&IF(COUNTIF(M13:M16,"⚠ AT RISK")+COUNTIF(M13:M16,"⚠ NO CAPACITY")>0,"Interviewer capacity is already strained at "&COUNTIF(M13:M16,"⚠ AT RISK")+COUNTIF(M13:M16,"⚠ NO CAPACITY")&" round(s). ","Current load is manageable. ")&"At the projected weekly inflow of "&$C$24&" recruiter screens, "&IF(COUNTIF(K25:K28,"*UNDERCAPACITY*")>0,"the pipeline will exceed capacity at "&COUNTIF(K25:K28,"*UNDERCAPACITY*")&" stage(s) — interviewer pool expansion needed.","capacity holds across all rounds.") -> As of May 4, 63 candidates are active in the FDE pipeline. Current load is manageable. At the projected weekly inflow of 40 recruiter screens, capacity holds across all rounds.

Sheet Pipeline by Platform
B4: FDE Recruiting Pipeline
B6: Platform | C6: Recruiter Screen | D6: R1 Invite | E6: R1 Conducted | F6: R2 Invite | G6: R2 Conducted | H6: R3 Invite | I6: R3 Conducted | J6: Offers | K6: Hires
B7: Databricks | C7: =COUNTIFS('Candidate Tracker'!$D$8:$D$256,$B7,'Candidate Tracker'!$Y$8:$Y$256,"Recruiter Screen - Being Scheduled")+COUNTIFS('Candidate Tracker'!$D$8:$D$256,$B7,'Candidate Tracker'!$Y$8:$Y$256,"Recruiter Screen - Invited")+COUNTIFS('Candidate Tracker'!$D$8:$D$256,$B7,'Candidate Tracker'!$Y$8:$Y$256,"Recruiter Screen - Conducted") -> 12 | D7: =COUNTIFS('Candidate Tracker'!$D$8:$D$256,$B7,'Candidate Tracker'!$Y$8:$Y$256,"Round 1 - Invite") -> 0 | E7: =COUNTIFS('Candidate Tracker'!$D$8:$D$256,$B7,'Candidate Tracker'!$Y$8:$Y$256,"Round 1 - Conducted") -> 2 | F7: =COUNTIFS('Candidate Tracker'!$D$8:$D$256,$B7,'Candidate Tracker'!$Y$8:$Y$256,"Round 2 - Invite") -> 1 | G7: =COUNTIFS('Candidate Tracker'!$D$8:$D$256,$B7,'Candidate Tracker'!$Y$8:$Y$256,"Round 2 - Conducted") -> 0 | H7: =COUNTIFS('Candidate Tracker'!$D$8:$D$256,$B7,'Candidate Tracker'!$Y$8:$Y$256,"Round 3 - Invite") -> 0 | I7: =COUNTIFS('Candidate Tracker'!$D$8:$D$256,$B7,'Candidate Tracker'!$Y$8:$Y$256,"Round 3 - Conducted") -> 0 | J7: =COUNTIFS('Candidate Tracker'!$D$8:$D$256,$B7,'Candidate Tracker'!$Y$8:$Y$256,"Offer Extended") -> 0 | K7: =COUNTIFS('Candidate Tracker'!$D$8:$D$256,$B7,'Candidate Tracker'!$Y$8:$Y$256,"Hired and Ready to Onboard") -> 0
B8: Palantir | C8: =COUNTIFS('Candidate Tracker'!$D$8:$D$256,$B8,'Candidate Tracker'!$Y$8:$Y$256,"Recruiter Screen - Being Scheduled")+COUNTIFS('Candidate Tracker'!$D$8:$D$256,$B8,'Candidate Tracker'!$Y$8:$Y$256,"Recruiter Screen - Invited")+COUNTIFS('Candidate Tracker'!$D$8:$D$256,$B8,'Candidate Tracker'!$Y$8:$Y$256,"Recruiter Screen - Conducted") -> 2 | D8: =COUNTIFS('Candidate Tracker'!$D$8:$D$256,$B8,'Candidate Tracker'!$Y$8:$Y$256,"Round 1 - Invite") -> 3 | E8: =COUNTIFS('Candidate Tracker'!$D$8:$D$256,$B8,'Candidate Tracker'!$Y$8:$Y$256,"Round 1 - Conducted") -> 3 | F8: =COUNTIFS('Candidate Tracker'!$D$8:$D$256,$B8,'Candidate Tracker'!$Y$8:$Y$256,"Round 2 - Invite") -> 2 | G8: =COUNTIFS('Candidate Tracker'!$D$8:$D$256,$B8,'Candidate Tracker'!$Y$8:$Y$256,"Round 2 - Conducted") -> 0 | H8: =COUNTIFS('Candidate Tracker'!$D$8:$D$256,$B8,'Candidate Tracker'!$Y$8:$Y$256,"Round 3 - Invite") -> 0 | I8: =COUNTIFS('Candidate Tracker'!$D$8:$D$256,$B8,'Candidate Tracker'!$Y$8:$Y$256,"Round 3 - Conducted") -> 0 | J8: =COUNTIFS('Candidate Tracker'!$D$8:$D$256,$B8,'Candidate Tracker'!$Y$8:$Y$256,"Offer Extended") -> 0 | K8: =COUNTIFS('Candidate Tracker'!$D$8:$D$256,$B8,'Candidate Tracker'!$Y$8:$Y$256,"Hired and Ready to Onboard") -> 0
B9: AWS | C9: =COUNTIFS('Candidate Tracker'!$D$8:$D$256,$B9,'Candidate Tracker'!$Y$8:$Y$256,"Recruiter Screen - Being Scheduled")+COUNTIFS('Candidate Tracker'!$D$8:$D$256,$B9,'Candidate Tracker'!$Y$8:$Y$256,"Recruiter Screen - Invited")+COUNTIFS('Candidate Tracker'!$D$8:$D$256,$B9,'Candidate Tracker'!$Y$8:$Y$256,"Recruiter Screen - Conducted") -> 6 | D9: =COUNTIFS('Candidate Tracker'!$D$8:$D$256,$B9,'Candidate Tracker'!$Y$8:$Y$256,"Round 1 - Invite") -> 5 | E9: =COUNTIFS('Candidate Tracker'!$D$8:$D$256,$B9,'Candidate Tracker'!$Y$8:$Y$256,"Round 1 - Conducted") -> 0 | F9: =COUNTIFS('Candidate Tracker'!$D$8:$D$256,$B9,'Candidate Tracker'!$Y$8:$Y$256,"Round 2 - Invite") -> 4 | G9: =COUNTIFS('Candidate Tracker'!$D$8:$D$256,$B9,'Candidate Tracker'!$Y$8:$Y$256,"Round 2 - Conducted") -> 0 | H9: =COUNTIFS('Candidate Tracker'!$D$8:$D$256,$B9,'Candidate Tracker'!$Y$8:$Y$256,"Round 3 - Invite") -> 1 | I9: =COUNTIFS('Candidate Tracker'!$D$8:$D$256,$B9,'Candidate Tracker'!$Y$8:$Y$256,"Round 3 - Conducted") -> 0 | J9: =COUNTIFS('Candidate Tracker'!$D$8:$D$256,$B9,'Candidate Tracker'!$Y$8:$Y$256,"Offer Extended") -> 0 | K9: =COUNTIFS('Candidate Tracker'!$D$8:$D$256,$B9,'Candidate Tracker'!$Y$8:$Y$256,"Hired and Ready to Onboard") -> 1
B10: Anthropic | C10: =COUNTIFS('Candidate Tracker'!$D$8:$D$256,$B10,'Candidate Tracker'!$Y$8:$Y$256,"Recruiter Screen - Being Scheduled")+COUNTIFS('Candidate Tracker'!$D$8:$D$256,$B10,'Candidate Tracker'!$Y$8:$Y$256,"Recruiter Screen - Invited")+COUNTIFS('Candidate Tracker'!$D$8:$D$256,$B10,'Candidate Tracker'!$Y$8:$Y$256,"Recruiter Screen - Conducted") -> 0 | D10: =COUNTIFS('Candidate Tracker'!$D$8:$D$256,$B10,'Candidate Tracker'!$Y$8:$Y$256,"Round 1 - Invite") -> 0 | E10: =COUNTIFS('Candidate Tracker'!$D$8:$D$256,$B10,'Candidate Tracker'!$Y$8:$Y$256,"Round 1 - Conducted") -> 0 | F10: =COUNTIFS('Candidate Tracker'!$D$8:$D$256,$B10,'Candidate Tracker'!$Y$8:$Y$256,"Round 2 - Invite") -> 0 | G10: =COUNTIFS('Candidate Tracker'!$D$8:$D$256,$B10,'Candidate Tracker'!$Y$8:$Y$256,"Round 2 - Conducted") -> 0 | H10: =COUNTIFS('Candidate Tracker'!$D$8:$D$256,$B10,'Candidate Tracker'!$Y$8:$Y$256,"Round 3 - Invite") -> 0 | I10: =COUNTIFS('Candidate Tracker'!$D$8:$D$256,$B10,'Candidate Tracker'!$Y$8:$Y$256,"Round 3 - Conducted") -> 0 | J10: =COUNTIFS('Candidate Tracker'!$D$8:$D$256,$B10,'Candidate Tracker'!$Y$8:$Y$256,"Offer Extended") -> 0 | K10: =COUNTIFS('Candidate Tracker'!$D$8:$D$256,$B10,'Candidate Tracker'!$Y$8:$Y$256,"Hired and Ready to Onboard") -> 0
B11: Google | C11: =COUNTIFS('Candidate Tracker'!$D$8:$D$256,$B11,'Candidate Tracker'!$Y$8:$Y$256,"Recruiter Screen - Being Scheduled")+COUNTIFS('Candidate Tracker'!$D$8:$D$256,$B11,'Candidate Tracker'!$Y$8:$Y$256,"Recruiter Screen - Invited")+COUNTIFS('Candidate Tracker'!$D$8:$D$256,$B11,'Candidate Tracker'!$Y$8:$Y$256,"Recruiter Screen - Conducted") -> 0 | D11: =COUNTIFS('Candidate Tracker'!$D$8:$D$256,$B11,'Candidate Tracker'!$Y$8:$Y$256,"Round 1 - Invite") -> 0 | E11: =COUNTIFS('Candidate Tracker'!$D$8:$D$256,$B11,'Candidate Tracker'!$Y$8:$Y$256,"Round 1 - Conducted") -> 0 | F11: =COUNTIFS('Candidate Tracker'!$D$8:$D$256,$B11,'Candidate Tracker'!$Y$8:$Y$256,"Round 2 - Invite") -> 0 | G11: =COUNTIFS('Candidate Tracker'!$D$8:$D$256,$B11,'Candidate Tracker'!$Y$8:$Y$256,"Round 2 - Conducted") -> 0 | H11: =COUNTIFS('Candidate Tracker'!$D$8:$D$256,$B11,'Candidate Tracker'!$Y$8:$Y$256,"Round 3 - Invite") -> 0 | I11: =COUNTIFS('Candidate Tracker'!$D$8:$D$256,$B11,'Candidate Tracker'!$Y$8:$Y$256,"Round 3 - Conducted") -> 0 | J11: =COUNTIFS('Candidate Tracker'!$D$8:$D$256,$B11,'Candidate Tracker'!$Y$8:$Y$256,"Offer Extended") -> 0 | K11: =COUNTIFS('Candidate Tracker'!$D$8:$D$256,$B11,'Candidate Tracker'!$Y$8:$Y$256,"Hired and Ready to Onboard") -> 0
B12: OpenAI | C12: =COUNTIFS('Candidate Tracker'!$D$8:$D$256,$B12,'Candidate Tracker'!$Y$8:$Y$256,"Recruiter Screen - Being Scheduled")+COUNTIFS('Candidate Tracker'!$D$8:$D$256,$B12,'Candidate Tracker'!$Y$8:$Y$256,"Recruiter Screen - Invited")+COUNTIFS('Candidate Tracker'!$D$8:$D$256,$B12,'Candidate Tracker'!$Y$8:$Y$256,"Recruiter Screen - Conducted") -> 0 | D12: =COUNTIFS('Candidate Tracker'!$D$8:$D$256,$B12,'Candidate Tracker'!$Y$8:$Y$256,"Round 1 - Invite") -> 0 | E12: =COUNTIFS('Candidate Tracker'!$D$8:$D$256,$B12,'Candidate Tracker'!$Y$8:$Y$256,"Round 1 - Conducted") -> 0 | F12: =COUNTIFS('Candidate Tracker'!$D$8:$D$256,$B12,'Candidate Tracker'!$Y$8:$Y$256,"Round 2 - Invite") -> 0 | G12: =COUNTIFS('Candidate Tracker'!$D$8:$D$256,$B12,'Candidate Tracker'!$Y$8:$Y$256,"Round 2 - Conducted") -> 0 | H12: =COUNTIFS('Candidate Tracker'!$D$8:$D$256,$B12,'Candidate Tracker'!$Y$8:$Y$256,"Round 3 - Invite") -> 0 | I12: =COUNTIFS('Candidate Tracker'!$D$8:$D$256,$B12,'Candidate Tracker'!$Y$8:$Y$256,"Round 3 - Conducted") -> 0 | J12: =COUNTIFS('Candidate Tracker'!$D$8:$D$256,$B12,'Candidate Tracker'!$Y$8:$Y$256,"Offer Extended") -> 0 | K12: =COUNTIFS('Candidate Tracker'!$D$8:$D$256,$B12,'Candidate Tracker'!$Y$8:$Y$256,"Hired and Ready to Onboard") -> 0
B13: Microsoft | C13: =COUNTIFS('Candidate Tracker'!$D$8:$D$256,$B13,'Candidate Tracker'!$Y$8:$Y$256,"Recruiter Screen - Being Scheduled")+COUNTIFS('Candidate Tracker'!$D$8:$D$256,$B13,'Candidate Tracker'!$Y$8:$Y$256,"Recruiter Screen - Invited")+COUNTIFS('Candidate Tracker'!$D$8:$D$256,$B13,'Candidate Tracker'!$Y$8:$Y$256,"Recruiter Screen - Conducted") -> 0 | D13: =COUNTIFS('Candidate Tracker'!$D$8:$D$256,$B13,'Candidate Tracker'!$Y$8:$Y$256,"Round 1 - Invite") -> 0 | E13: =COUNTIFS('Candidate Tracker'!$D$8:$D$256,$B13,'Candidate Tracker'!$Y$8:$Y$256,"Round 1 - Conducted") -> 0 | F13: =COUNTIFS('Candidate Tracker'!$D$8:$D$256,$B13,'Candidate Tracker'!$Y$8:$Y$256,"Round 2 - Invite") -> 0 | G13: =COUNTIFS('Candidate Tracker'!$D$8:$D$256,$B13,'Candidate Tracker'!$Y$8:$Y$256,"Round 2 - Conducted") -> 0 | H13: =COUNTIFS('Candidate Tracker'!$D$8:$D$256,$B13,'Candidate Tracker'!$Y$8:$Y$256,"Round 3 - Invite") -> 0 | I13: =COUNTIFS('Candidate Tracker'!$D$8:$D$256,$B13,'Candidate Tracker'!$Y$8:$Y$256,"Round 3 - Conducted") -> 0 | J13: =COUNTIFS('Candidate Tracker'!$D$8:$D$256,$B13,'Candidate Tracker'!$Y$8:$Y$256,"Offer Extended") -> 0 | K13: =COUNTIFS('Candidate Tracker'!$D$8:$D$256,$B13,'Candidate Tracker'!$Y$8:$Y$256,"Hired and Ready to Onboard") -> 0
B14: Snowflake | C14: =COUNTIFS('Candidate Tracker'!$D$8:$D$256,$B14,'Candidate Tracker'!$Y$8:$Y$256,"Recruiter Screen - Being Scheduled")+COUNTIFS('Candidate Tracker'!$D$8:$D$256,$B14,'Candidate Tracker'!$Y$8:$Y$256,"Recruiter Screen - Invited")+COUNTIFS('Candidate Tracker'!$D$8:$D$256,$B14,'Candidate Tracker'!$Y$8:$Y$256,"Recruiter Screen - Conducted") -> 6 | D14: =COUNTIFS('Candidate Tracker'!$D$8:$D$256,$B14,'Candidate Tracker'!$Y$8:$Y$256,"Round 1 - Invite") -> 3 | E14: =COUNTIFS('Candidate Tracker'!$D$8:$D$256,$B14,'Candidate Tracker'!$Y$8:$Y$256,"Round 1 - Conducted") -> 0 | F14: =COUNTIFS('Candidate Tracker'!$D$8:$D$256,$B14,'Candidate Tracker'!$Y$8:$Y$256,"Round 2 - Invite") -> 0 | G14: =COUNTIFS('Candidate Tracker'!$D$8:$D$256,$B14,'Candidate Tracker'!$Y$8:$Y$256,"Round 2 - Conducted") -> 0 | H14: =COUNTIFS('Candidate Tracker'!$D$8:$D$256,$B14,'Candidate Tracker'!$Y$8:$Y$256,"Round 3 - Invite") -> 0 | I14: =COUNTIFS('Candidate Tracker'!$D$8:$D$256,$B14,'Candidate Tracker'!$Y$8:$Y$256,"Round 3 - Conducted") -> 0 | J14: =COUNTIFS('Candidate Tracker'!$D$8:$D$256,$B14,'Candidate Tracker'!$Y$8:$Y$256,"Offer Extended") -> 0 | K14: =COUNTIFS('Candidate Tracker'!$D$8:$D$256,$B14,'Candidate Tracker'!$Y$8:$Y$256,"Hired and Ready to Onboard") -> 0
B15: Frontier GenAI | C15: =COUNTIFS('Candidate Tracker'!$D$8:$D$256,$B15,'Candidate Tracker'!$Y$8:$Y$256,"Recruiter Screen - Being Scheduled")+COUNTIFS('Candidate Tracker'!$D$8:$D$256,$B15,'Candidate Tracker'!$Y$8:$Y$256,"Recruiter Screen - Invited")+COUNTIFS('Candidate Tracker'!$D$8:$D$256,$B15,'Candidate Tracker'!$Y$8:$Y$256,"Recruiter Screen - Conducted") -> 8 | D15: =COUNTIFS('Candidate Tracker'!$D$8:$D$256,$B15,'Candidate Tracker'!$Y$8:$Y$256,"Round 1 - Invite") -> 4 | E15: =COUNTIFS('Candidate Tracker'!$D$8:$D$256,$B15,'Candidate Tracker'!$Y$8:$Y$256,"Round 1 - Conducted") -> 0 | F15: =COUNTIFS('Candidate Tracker'!$D$8:$D$256,$B15,'Candidate Tracker'!$Y$8:$Y$256,"Round 2 - Invite") -> 1 | G15: =COUNTIFS('Candidate Tracker'!$D$8:$D$256,$B15,'Candidate Tracker'!$Y$8:$Y$256,"Round 2 - Conducted") -> 0 | H15: =COUNTIFS('Candidate Tracker'!$D$8:$D$256,$B15,'Candidate Tracker'!$Y$8:$Y$256,"Round 3 - Invite") -> 0 | I15: =COUNTIFS('Candidate Tracker'!$D$8:$D$256,$B15,'Candidate Tracker'!$Y$8:$Y$256,"Round 3 - Conducted") -> 0 | J15: =COUNTIFS('Candidate Tracker'!$D$8:$D$256,$B15,'Candidate Tracker'!$Y$8:$Y$256,"Offer Extended") -> 0 | K15: =COUNTIFS('Candidate Tracker'!$D$8:$D$256,$B15,'Candidate Tracker'!$Y$8:$Y$256,"Hired and Ready to Onboard") -> 0
B16: TOTAL | C16: =SUM(C7:C15) -> 34 | D16: =SUM(D7:D15) -> 15 | E16: =SUM(E7:E15) -> 5 | F16: =SUM(F7:F15) -> 8 | G16: =SUM(G7:G15) -> 0 | H16: =SUM(H7:H15) -> 1 | I16: =SUM(I7:I15) -> 0 | J16: =SUM(J7:J15) -> 0 | K16: =SUM(K7:K15) -> 1 | M16: =SUM(C16:K16) -> 64

Sheet Candidate Tracker
B4: FDE Candidate Tracker
B5: Add one row per candidate. Use the dropdowns where available. All dashboard metrics and the platform pipeline update automatically from this sheet. Do NOT delete columns or rename headers.
B7: Candidate ID | C7: Candidate Name | D7: Platform / Alliance | E7: Source | F7: Date Applied | G7: Recruiter | H7: Recruiter Screen Days in Queue | I7: Recruiter Screen Date | J7: Recruiter Screen Outcome | K7: Round 1 Days in Queue | L7: Round 1 Date | M7: Round 1 Interviewer | N7: Round 1 Outcome | O7: Round 2 Days in Queue | P7: Round 2 Date | Q7: Round 2 Panelist 1 | R7: Round 2 Panelist 2 | S7: Round 2 Panelist 3 | T7: Round 2 Outcome | U7: Round 3 Days in Queue | V7: Round 3 Date | W7: Round 3 Interviewer | X7: Round 3 Outcome | Y7: Current Stage | Z7: Status | AA7: Hire Date | AB7: Start Date | AC7: Notes
B8: =IF(C8="","","FDE-"&TEXT(ROW()-7,"000")) -> FDE-001 | C8: Ackermann, Mylin | D8: AWS | E8: LinkedIn | G8: Matt Whittle (mwhittle@deloitte.com) | H8: =IF(OR(F8="",F8>TODAY()),"N/A",IF(I8="",TODAY()-F8,I8-F8)) -> N/A | J8: Pass | K8: =IF(OR(J8="Fail",I8="",I8>TODAY()),"N/A",IF(L8="",TODAY()-I8,L8-I8)) -> N/A | L8: 46148 | M8: Faruk Muratovic | O8: =IF(OR(N8="Fail",L8="",L8>TODAY()),"N/A",IF(P8="",TODAY()-L8,P8-L8)) -> N/A | U8: =IF(OR(T8="Fail",P8="",P8>TODAY()),"N/A",IF(V8="",TODAY()-P8,V8-P8)) -> N/A | Y8: Round 1 - Invite | Z8: Active
B9: =IF(C9="","","FDE-"&TEXT(ROW()-7,"000")) -> FDE-002 | C9: BACHAPALLY, SAI OOTEJ REDDY | D9: Snowflake | E9: LinkedIn | G9: Paul Lemmon (plemmon@deloitte.com) | H9: =IF(OR(F9="",F9>TODAY()),"N/A",IF(I9="",TODAY()-F9,I9-F9)) -> N/A | J9: Pass | K9: =IF(OR(J9="Fail",I9="",I9>TODAY()),"N/A",IF(L9="",TODAY()-I9,L9-I9)) -> N/A | L9: 46148 | M9: Jillian Wanner | O9: =IF(OR(N9="Fail",L9="",L9>TODAY()),"N/A",IF(P9="",TODAY()-L9,P9-L9)) -> N/A | U9: =IF(OR(T9="Fail",P9="",P9>TODAY()),"N/A",IF(V9="",TODAY()-P9,V9-P9)) -> N/A | Y9: Round 1 - Invite | Z9: Active
B10: =IF(C10="","","FDE-"&TEXT(ROW()-7,"000")) -> FDE-003 | C10: Sanders, Evan | D10: AWS | E10: LinkedIn | G10: Matt Whittle (mwhittle@deloitte.com) | H10: =IF(OR(F10="",F10>TODAY()),"N/A",IF(I10="",TODAY()-F10,I10-F10)) -> N/A | J10: Pass | K10: =IF(OR(J10="Fail",I10="",I10>TODAY()),"N/A",IF(L10="",TODAY()-I10,L10-I10)) -> N/A | L10: 46148 | M10: Mike Schuler | O10: =IF(OR(N10="Fail",L10="",L10>TODAY()),"N/A",IF(P10="",TODAY()-L10,P10-L10)) -> N/A | U10: =IF(OR(T10="Fail",P10="",P10>TODAY()),"N/A",IF(V10="",TODAY()-P10,V10-P10)) -> N/A | Y10: Round 1 - Invite | Z10: Active
B11: =IF(C11="","","FDE-"&TEXT(ROW()-7,"000")) -> FDE-004 | C11: Sinha, Akash | D11: AWS | E11: LinkedIn | G11: Matt Whittle (mwhittle@deloitte.com) | H11: =IF(OR(F11="",F11>TODAY()),"N/A",IF(I11="",TODAY()-F11,I11-F11)) -> N/A | J11: Pass | K11: =IF(OR(J11="Fail",I11="",I11>TODAY()),"N/A",IF(L11="",TODAY()-I11,L11-I11)) -> N/A | L11: 46147 | M11: Mike Schuler | O11: =IF(OR(N11="Fail",L11="",L11>TODAY()),"N/A",IF(P11="",TODAY()-L11,P11-L11)) -> N/A | U11: =IF(OR(T11="Fail",P11="",P11>TODAY()),"N/A",IF(V11="",TODAY()-P11,V11-P11)) -> N/A | Y11: Round 1 - Invite | Z11: Active
B12: =IF(C12="","","FDE-"&TEXT(ROW()-7,"000")) -> FDE-005 | C12: Kadarla, Bharath | D12: Palantir | E12: Direct Employers | G12: Paul Lemmon (plemmon@deloitte.com) | H12: =IF(OR(F12="",F12>TODAY()),"N/A",IF(I12="",TODAY()-F12,I12-F12)) -> N/A | J12: Pass | K12: =IF(OR(J12="Fail",I12="",I12>TODAY()),"N/A",IF(L12="",TODAY()-I12,L12-I12)) -> N/A | L12: 46146 | M12: Mike Schuler | O12: =IF(OR(N12="Fail",L12="",L12>TODAY()),"N/A",IF(P12="",TODAY()-L12,P12-L12)) -> 0 | U12: =IF(OR(T12="Fail",P12="",P12>TODAY()),"N/A",IF(V12="",TODAY()-P12,V12-P12)) -> N/A | Y12: Round 1 - Invite | Z12: Active
B13: =IF(C13="","","FDE-"&TEXT(ROW()-7,"000")) -> FDE-006 | C13: Boles, Hunter | D13: Frontier GenAI | E13: LinkedIn | G13: Diana Gutman (diagutman@deloitte.com) | H13: =IF(OR(F13="",F13>TODAY()),"N/A",IF(I13="",TODAY()-F13,I13-F13)) -> N/A | J13: Pass | K13: =IF(OR(J13="Fail",I13="",I13>TODAY()),"N/A",IF(L13="",TODAY()-I13,L13-I13)) -> N/A | L13: 46143 | M13: Lecong, Phuong | O13: =IF(OR(N13="Fail",L13="",L13>TODAY()),"N/A",IF(P13="",TODAY()-L13,P13-L13)) -> 3 | U13: =IF(OR(T13="Fail",P13="",P13>TODAY()),"N/A",IF(V13="",TODAY()-P13,V13-P13)) -> N/A | Y13: Round 1 - Invite | Z13: Active
B14: =IF(C14="","","FDE-"&TEXT(ROW()-7,"000")) -> FDE-007 | C14: Elizondo Sanchez, Angel Adrian | D14: Palantir | E14: Employee Referral | G14: Paul Lemmon (plemmon@deloitte.com) | H14: =IF(OR(F14="",F14>TODAY()),"N/A",IF(I14="",TODAY()-F14,I14-F14)) -> N/A | J14: Pass | K14: =IF(OR(J14="Fail",I14="",I14>TODAY()),"N/A",IF(L14="",TODAY()-I14,L14-I14)) -> N/A | L14: 46143 | M14: Jon Smyrl | O14: =IF(OR(N14="Fail",L14="",L14>TODAY()),"N/A",IF(P14="",TODAY()-L14,P14-L14)) -> 3 | U14: =IF(OR(T14="Fail",P14="",P14>TODAY()),"N/A",IF(V14="",TODAY()-P14,V14-P14)) -> N/A | Y14: Round 1 - Invite | Z14: Active
B15: =IF(C15="","","FDE-"&TEXT(ROW()-7,"000")) -> FDE-008 | C15: Marathe, Aparna | D15: Frontier GenAI | E15: Alumni Referral | G15: Diana Gutman (diagutman@deloitte.com) | H15: =IF(OR(F15="",F15>TODAY()),"N/A",IF(I15="",TODAY()-F15,I15-F15)) -> N/A | J15: Pass | K15: =IF(OR(J15="Fail",I15="",I15>TODAY()),"N/A",IF(L15="",TODAY()-I15,L15-I15)) -> N/A | L15: 46143 | M15: Phuong Lecong | O15: =IF(OR(N15="Fail",L15="",L15>TODAY()),"N/A",IF(P15="",TODAY()-L15,P15-L15)) -> 3 | U15: =IF(OR(T15="Fail",P15="",P15>TODAY()),"N/A",IF(V15="",TODAY()-P15,V15-P15)) -> N/A | Y15: Round 1 - Invite | Z15: Active
B16: =IF(C16="","","FDE-"&TEXT(ROW()-7,"000")) -> FDE-009 | C16: Vajrapu, Satya Sai Naga Venkata Kumar | D16: AWS | E16: LinkedIn | G16: Matt Whittle (mwhittle@deloitte.com) | H16: =IF(OR(F16="",F16>TODAY()),"N/A",IF(I16="",TODAY()-F16,I16-F16)) -> N/A | J16: Pass | K16: =IF(OR(J16="Fail",I16="",I16>TODAY()),"N/A",IF(L16="",TODAY()-I16,L16-I16)) -> N/A | L16: 46143 | M16: Faruk Muratovic | O16: =IF(OR(N16="Fail",L16="",L16>TODAY()),"N/A",IF(P16="",TODAY()-L16,P16-L16)) -> 3 | U16: =IF(OR(T16="Fail",P16="",P16>TODAY()),"N/A",IF(V16="",TODAY()-P16,V16-P16)) -> N/A | Y16: Round 1 - Invite | Z16: Active
B17: =IF(C17="","","FDE-"&TEXT(ROW()-7,"000")) -> FDE-010 | C17: Dandu, Narendar | D17: Palantir | E17: Indeed | G17: Paul Lemmon (plemmon@deloitte.com) | H17: =IF(OR(F17="",F17>TODAY()),"N/A",IF(I17="",TODAY()-F17,I17-F17)) -> N/A | J17: Pass | K17: =IF(OR(J17="Fail",I17="",I17>TODAY()),"N/A",IF(L17="",TODAY()-I17,L17-I17)) -> N/A | L17: 46142 | M17: Mike Schuler | O17: =IF(OR(N17="Fail",L17="",L17>TODAY()),"N/A",IF(P17="",TODAY()-L17,P17-L17)) -> 4 | U17: =IF(OR(T17="Fail",P17="",P17>TODAY()),"N/A",IF(V17="",TODAY()-P17,V17-P17)) -> N/A | Y17: Round 1 - Conducted | Z17: Active
B18: =IF(C18="","","FDE-"&TEXT(ROW()-7,"000")) -> FDE-011 | C18: Christoforidis, Alexandros | D18: Palantir | E18: Employee Referral | G18: Paul Lemmon (plemmon@deloitte.com) | H18: =IF(OR(F18="",F18>TODAY()),"N/A",IF(I18="",TODAY()-F18,I18-F18)) -> N/A | J18: Pass | K18: =IF(OR(J18="Fail",I18="",I18>TODAY()),"N/A",IF(L18="",TODAY()-I18,L18-I18)) -> N/A | L18: 46141 | M18: Mike Schuler | O18: =IF(OR(N18="Fail",L18="",L18>TODAY()),"N/A",IF(P18="",TODAY()-L18,P18-L18)) -> 5 | U18: =IF(OR(T18="Fail",P18="",P18>TODAY()),"N/A",IF(V18="",TODAY()-P18,V18-P18)) -> N/A | Y18: Round 1 - Conducted | Z18: Active
B19: =IF(C19="","","FDE-"&TEXT(ROW()-7,"000")) -> FDE-012 | C19: Ojha, Keerti | D19: Palantir | E19: LinkedIn | G19: Paul Lemmon (plemmon@deloitte.com) | H19: =IF(OR(F19="",F19>TODAY()),"N/A",IF(I19="",TODAY()-F19,I19-F19)) -> N/A | J19: Pass | K19: =IF(OR(J19="Fail",I19="",I19>TODAY()),"N/A",IF(L19="",TODAY()-I19,L19-I19)) -> N/A | L19: 46141 | M19: Mike Schuler | O19: =IF(OR(N19="Fail",L19="",L19>TODAY()),"N/A",IF(P19="",TODAY()-L19,P19-L19)) -> 5 | U19: =IF(OR(T19="Fail",P19="",P19>TODAY()),"N/A",IF(V19="",TODAY()-P19,V19-P19)) -> N/A | Y19: Round 1 - Conducted | Z19: Active
... B21: =IF(C21="","","FDE-"&TEXT(ROW()-7,"000")) -> FDE-014 | C21: Baskaran, Ramasamy | D21: Databricks | E21: Indeed | G21: Matt Whittle (mwhittle@deloitte.com) | H21: =IF(OR(F21="",F21>TODAY()),"N/A",IF(I21="",TODAY()-F21,I21-F21)) -> N/A | J21: Pass | K21: =IF(OR(J21="Fail",I21="",I21>TODAY()),"N/A",IF(L21="",TODAY()-I21,L21-I21)) -> N/A | L21: 46140 | M21: Brijraj Limbad | O21: =IF(OR(N21="Fail",L21="",L21>TODAY()),"N/A",IF(P21="",TODAY()-L21,P21-L21)) -> 6 | U21: =IF(OR(T21="Fail",P21="",P21>TODAY()),"N/A",IF(V21="",TODAY()-P21,V21-P21)) -> N/A | Y21: Round 1 - Conducted | Z21: Active
B22: =IF(C22="","","FDE-"&TEXT(ROW()-7,"000")) -> FDE-015 | C22: Dewan, Anupam | D22: AWS | E22: LinkedIn | G22: Matt Whittle (mwhittle@deloitte.com) | H22: =IF(OR(F22="",F22>TODAY()),"N/A",IF(I22="",TODAY()-F22,I22-F22)) -> N/A | J22: Pass | K22: =IF(OR(J22="Fail",I22="",I22>TODAY()),"N/A",IF(L22="",TODAY()-I22,L22-I22)) -> N/A | L22: 46139 | M22: Faruk Muratovic | N22: Pass | O22: =IF(OR(N22="Fail",L22="",L22>TODAY()),"N/A",IF(P22="",TODAY()-L22,P22-L22)) -> 7 | U22: =IF(OR(T22="Fail",P22="",P22>TODAY()),"N/A",IF(V22="",TODAY()-P22,V22-P22)) -> N/A | Y22: Round 2 - Invite | Z22: Active
B23: =IF(C23="","","FDE-"&TEXT(ROW()-7,"000")) -> FDE-016 | C23: Kakarla, Vinod | D23: Palantir | E23: LinkedIn | G23: Paul Lemmon (plemmon@deloitte.com) | H23: =IF(OR(F23="",F23>TODAY()),"N/A",IF(I23="",TODAY()-F23,I23-F23)) -> N/A | J23: Pass | K23: =IF(OR(J23="Fail",I23="",I23>TODAY()),"N/A",IF(L23="",TODAY()-I23,L23-I23)) -> N/A | L23: 46139 | M23: Jon Smyrl | N23: Pass | O23: =IF(OR(N23="Fail",L23="",L23>TODAY()),"N/A",IF(P23="",TODAY()-L23,P23-L23)) -> 8 | P23: 46147 | Q23: Faruk Muratovic | R23: Phuong Lecong | U23: =IF(OR(T23="Fail",P23="",P23>TODAY()),"N/A",IF(V23="",TODAY()-P23,V23-P23)) -> N/A | Y23: Round 2 - Invite | Z23: Active
B24: =IF(C24="","","FDE-"&TEXT(ROW()-7,"000")) -> FDE-017 | C24: Modh, Pranav | D24: Palantir | E24: LinkedIn | G24: Paul Lemmon (plemmon@deloitte.com) | H24: =IF(OR(F24="",F24>TODAY()),"N/A",IF(I24="",TODAY()-F24,I24-F24)) -> N/A | J24: Pass | K24: =IF(OR(J24="Fail",I24="",I24>TODAY()),"N/A",IF(L24="",TODAY()-I24,L24-I24)) -> N/A | L24: 46136 | M24: Jon Smyrl | N24: Pass | O24: =IF(OR(N24="Fail",L24="",L24>TODAY()),"N/A",IF(P24="",TODAY()-L24,P24-L24)) -> 10 | P24: 46146 | Q24: John Zimmerman | R24: Mike Urbanczyk | U24: =IF(OR(T24="Fail",P24="",P24>TODAY()),"N/A",IF(V24="",TODAY()-P24,V24-P24)) -> 0 | Y24: Round 2 - Invite | Z24: Active
B25: =IF(C25="","","FDE-"&TEXT(ROW()-7,"000")) -> FDE-018 | C25: Su, Shuo | D25: Databricks | E25: LinkedIn | G25: Matt Whittle (mwhittle@deloitte.com) | H25: =IF(OR(F25="",F25>TODAY()),"N/A",IF(I25="",TODAY()-F25,I25-F25)) -> N/A | J25: Pass | K25: =IF(OR(J25="Fail",I25="",I25>TODAY()),"N/A",IF(L25="",TODAY()-I25,L25-I25)) -> N/A | L25: 46136 | M25: Brijraj Limbad | O25: =IF(OR(N25="Fail",L25="",L25>TODAY()),"N/A",IF(P25="",TODAY()-L25,P25-L25)) -> 10 | U25: =IF(OR(T25="Fail",P25="",P25>TODAY()),"N/A",IF(V25="",TODAY()-P25,V25-P25)) -> N/A | Y25: Round 1 - Conducted | Z25: Active
B26: =IF(C26="","","FDE-"&TEXT(ROW()-7,"000")) -> FDE-019 | C26: Vadde, Krishnan | D26: AWS | E26: LinkedIn | G26: Matt Whittle (mwhittle@deloitte.com) | H26: =IF(OR(F26="",F26>TODAY()),"N/A",IF(I26="",TODAY()-F26,I26-F26)) -> N/A | J26: Pass | K26: =IF(OR(J26="Fail",I26="",I26>TODAY()),"N/A",IF(L26="",TODAY()-I26,L26-I26)) -> N/A | L26: 46136 | M26: Faruk Muratovic | N26: Fail | O26: =IF(OR(N26="Fail",L26="",L26>TODAY()),"N/A",IF(P26="",TODAY()-L26,P26-L26)) -> N/A | U26: =IF(OR(T26="Fail",P26="",P26>TODAY()),"N/A",IF(V26="",TODAY()-P26,V26-P26)) -> N/A | Y26: Round 2 - Invite | Z26: Active
B27: =IF(C27="","","FDE-"&TEXT(ROW()-7,"000")) -> FDE-020 | C27: Muley, Gaurav | D27: AWS | E27: Agency Referral | G27: Matt Whittle (mwhittle@deloitte.com) | H27: =IF(OR(F27="",F27>TODAY()),"N/A",IF(I27="",TODAY()-F27,I27-F27)) -> N/A | J27: Pass | K27: =IF(OR(J27="Fail",I27="",I27>TODAY()),"N/A",IF(L27="",TODAY()-I27,L27-I27)) -> N/A | L27: 46132 | M27: Tony Witherspoon | N27: Pass | O27: =IF(OR(N27="Fail",L27="",L27>TODAY()),"N/A",IF(P27="",TODAY()-L27,P27-L27)) -> 14 | U27: =IF(OR(T27="Fail",P27="",P27>TODAY()),"N/A",IF(V27="",TODAY()-P27,V27-P27)) -> N/A | Y27: Round 2 - Invite | Z27: Active
B28: =IF(C28="","","FDE-"&TEXT(ROW()-7,"000")) -> FDE-021 | C28: Gibbs, Justin | D28: AWS | E28: Deloitte US Careers | G28: Matt Whittle (mwhittle@deloitte.com) | H28: =IF(OR(F28="",F28>TODAY()),"N/A",IF(I28="",TODAY()-F28,I28-F28)) -> N/A | J28: Pass | K28: =IF(OR(J28="Fail",I28="",I28>TODAY()),"N/A",IF(L28="",TODAY()-I28,L28-I28)) -> N/A | L28: 46129 | M28: Faruk Muratovic | N28: Pass | O28: =IF(OR(N28="Fail",L28="",L28>TODAY()),"N/A",IF(P28="",TODAY()-L28,P28-L28)) -> 14 | P28: 46143 | Q28: Prakul Sharma | R28: Jillian Wanner | U28: =IF(OR(T28="Fail",P28="",P28>TODAY()),"N/A",IF(V28="",TODAY()-P28,V28-P28)) -> 3 | Y28: Round 2 - Invite | Z28: Active
B29: =IF(C29="","","FDE-"&TEXT(ROW()-7,"000")) -> FDE-022 | C29: Hourani, Mark | D29: Frontier GenAI | E29: Agency Referral | G29: Diana Gutman (diagutman@deloitte.com) | H29: =IF(OR(F29="",F29>TODAY()),"N/A",IF(I29="",TODAY()-F29,I29-F29)) -> N/A | J29: Pass | K29: =IF(OR(J29="Fail",I29="",I29>TODAY()),"N/A",IF(L29="",TODAY()-I29,L29-I29)) -> N/A | L29: 46129 | M29: Jon Smyrl | N29: Pass | O29: =IF(OR(N29="Fail",L29="",L29>TODAY()),"N/A",IF(P29="",TODAY()-L29,P29-L29)) -> 13 | P29: 46142 | Q29: Tim Juravic (Did not join) | R29: Chris Carella | T29: Pass | U29: =IF(OR(T29="Fail",P29="",P29>TODAY()),"N/A",IF(V29="",TODAY()-P29,V29-P29)) -> 4 | W29: Faruk Muratovic | Y29: Round 2 - Invite | Z29: Active
B30: =IF(C30="","","FDE-"&TEXT(ROW()-7,"000")) -> FDE-023 | C30: Miranda, Maxcimiliano | D30: Frontier GenAI | E30: Indeed | G30: Diana Gutman (diagutman@deloitte.com) | H30: =IF(OR(F30="",F30>TODAY()),"N/A",IF(I30="",TODAY()-F30,I30-F30)) -> N/A | J30: Pass | K30: =IF(OR(J30="Fail",I30="",I30>TODAY()),"N/A",IF(L30="",TODAY()-I30,L30-I30)) -> N/A | L30: 46129 | M30: Jon Smyrl | N30: Pass | O30: =IF(OR(N30="Fail",L30="",L30>TODAY()),"N/A",IF(P30="",TODAY()-L30,P30-L30)) -> 17 | U30: =IF(OR(T30="Fail",P30="",P30>TODAY()),"N/A",IF(V30="",TODAY()-P30,V30-P30)) -> N/A | Y30: Withdrew | Z30: Withdrew
B31: =IF(C31="","","FDE-"&TEXT(ROW()-7,"000")) -> FDE-024 | C31: Ganguly, Paromita | D31: AWS | E31: Employee Referral | G31: Matt Whittle (mwhittle@deloitte.com) | H31: =IF(OR(F31="",F31>TODAY()),"N/A",IF(I31="",TODAY()-F31,I31-F31)) -> N/A | J31: Pass | K31: =IF(OR(J31="Fail",I31="",I31>TODAY()),"N/A",IF(L31="",TODAY()-I31,L31-I31)) -> N/A | L31: 46119 | M31: Chris Carella | N31: Pass | O31: =IF(OR(N31="Fail",L31="",L31>TODAY()),"N/A",IF(P31="",TODAY()-L31,P31-L31)) -> 15 | P31: 46134 | Q31: Faruk Muratovic | R31: Mike Schuler | U31: =IF(OR(T31="Fail",P31="",P31>TODAY()),"N/A",IF(V31="",TODAY()-P31,V31-P31)) -> 14 | V31: 46148 | W31: Mark Urbanczyk | Y31: Round 3 - Invite | Z31: Active
B32: =IF(C32="","","FDE-"&TEXT(ROW()-7,"000")) -> FDE-025 | C32: Falen, Zachary | D32: AWS | E32: Rehire | G32: Matt Whittle (mwhittle@deloitte.com) | H32: =IF(OR(F32="",F32>TODAY()),"N/A",IF(I32="",TODAY()-F32,I32-F32)) -> N/A | J32: Pass | K32: =IF(OR(J32="Fail",I32="",I32>TODAY()),"N/A",IF(L32="",TODAY()-I32,L32-I32)) -> N/A | L32: 46105 | M32: Tim Juravich | N32: Pass | O32: =IF(OR(N32="Fail",L32="",L32>TODAY()),"N/A",IF(P32="",TODAY()-L32,P32-L32)) -> 3 | P32: 46108 | Q32: Chris Carella | T32: Pass | U32: =IF(OR(T32="Fail",P32="",P32>TODAY()),"N/A",IF(V32="",TODAY()-P32,V32-P32)) -> 8 | V32: 46116 | W32: Faruk Muratovic | X32: Pass | Y32: Hired and Ready to Onboard | Z32: Hired | AA32: 46133 | AB32: 45823
B33: =IF(C33="","","FDE-"&TEXT(ROW()-7,"000")) -> FDE-026 | C33: Adhikari, Shashi | D33: Frontier GenAI | E33: Employee Referral | G33: Diana Gutman (diagutman@deloitte.com) | H33: =IF(OR(F33="",F33>TODAY()),"N/A",IF(I33="",TODAY()-F33,I33-F33)) -> N/A | J33: Pass | K33: =IF(OR(J33="Fail",I33="",I33>TODAY()),"N/A",IF(L33="",TODAY()-I33,L33-I33)) -> N/A | O33: =IF(OR(N33="Fail",L33="",L33>TODAY()),"N/A",IF(P33="",TODAY()-L33,P33-L33)) -> N/A | U33: =IF(OR(T33="Fail",P33="",P33>TODAY()),"N/A",IF(V33="",TODAY()-P33,V33-P33)) -> N/A | Y33: Recruiter Screen - Invited | Z33: Active
B34: =IF(C34="","","FDE-"&TEXT(ROW()-7,"000")) -> FDE-027 | C34: Akram, Russell | D34: Frontier GenAI | E34: Other - Conference or Alliance | G34: Diana Gutman (diagutman@deloitte.com) | H34: =IF(OR(F34="",F34>TODAY()),"N/A",IF(I34="",TODAY()-F34,I34-F34)) -> N/A | J34: Pass | K34: =IF(OR(J34="Fail",I34="",I34>TODAY()),"N/A",IF(L34="",TODAY()-I34,L34-I34)) -> N/A | O34: =IF(OR(N34="Fail",L34="",L34>TODAY()),"N/A",IF(P34="",TODAY()-L34,P34-L34)) -> N/A | U34: =IF(OR(T34="Fail",P34="",P34>TODAY()),"N/A",IF(V34="",TODAY()-P34,V34-P34)) -> N/A | Y34: Recruiter Screen - Conducted | Z34: Active
B35: =IF(C35="","","FDE-"&TEXT(ROW()-7,"000")) -> FDE-028 | C35: Alterman, Hershel | D35: Frontier GenAI | E35: LinkedIn | G35: Diana Gutman (diagutman@deloitte.com) | H35: =IF(OR(F35="",F35>TODAY()),"N/A",IF(I35="",TODAY()-F35,I35-F35)) -> N/A | J35: Pass | K35: =IF(OR(J35="Fail",I35="",I35>TODAY()),"N/A",IF(L35="",TODAY()-I35,L35-I35)) -> N/A | O35: =IF(OR(N35="Fail",L35="",L35>TODAY()),"N/A",IF(P35="",TODAY()-L35,P35-L35)) -> N/A | U35: =IF(OR(T35="Fail",P35="",P35>TODAY()),"N/A",IF(V35="",TODAY()-P35,V35-P35)) -> N/A | Y35: Recruiter Screen - Being Scheduled | Z35: Active
B36: =IF(C36="","","FDE-"&TEXT(ROW()-7,"000")) -> FDE-029 | C36: Ananthanarayan, Sanjay | D36: AWS | E36: LinkedInSponsored | G36: Matt Whittle (mwhittle@deloitte.com) | H36: =IF(OR(F36="",F36>TODAY()),"N/A",IF(I36="",TODAY()-F36,I36-F36)) -> N/A | J36: Pass | K36: =IF(OR(J36="Fail",I36="",I36>TODAY()),"N/A",IF(L36="",TODAY()-I36,L36-I36)) -> N/A | O36: =IF(OR(N36="Fail",L36="",L36>TODAY()),"N/A",IF(P36="",TODAY()-L36,P36-L36)) -> N/A | U36: =IF(OR(T36="Fail",P36="",P36>TODAY()),"N/A",IF(V36="",TODAY()-P36,V36-P36)) -> N/A | Y36: Recruiter Screen - Invited | Z36: Active
B37: =IF(C37="","","FDE-"&TEXT(ROW()-7,"000")) -> FDE-030 | C37: Ananthapadmanabhan, Sivasubramanian | D37: Databricks | E37: Indeed | G37: Matt Whittle (mwhittle@deloitte.com) | H37: =IF(OR(F37="",F37>TODAY()),"N/A",IF(I37="",TODAY()-F37,I37-F37)) -> N/A | J37: Pass | K37: =IF(OR(J37="Fail",I37="",I37>TODAY()),"N/A",IF(L37="",TODAY()-I37,L37-I37)) -> N/A | O37: =IF(OR(N37="Fail",L37="",L37>TODAY()),"N/A",IF(P37="",TODAY()-L37,P37-L37)) -> N/A | U37: =IF(OR(T37="Fail",P37="",P37>TODAY()),"N/A",IF(V37="",TODAY()-P37,V37-P37)) -> N/A | Y37: Recruiter Screen - Invited | Z37: Active
B38: =IF(C38="","","FDE-"&TEXT(ROW()-7,"000")) -> FDE-031 | C38: Avasarala, Sriharshitha | D38: Frontier GenAI | E38: LinkedIn | G38: Diana Gutman (diagutman@deloitte.com) | H38: =IF(OR(F38="",F38>TODAY()),"N/A",IF(I38="",TODAY()-F38,I38-F38)) -> N/A | J38: Pass | K38: =IF(OR(J38="Fail",I38="",I38>TODAY()),"N/A",IF(L38="",TODAY()-I38,L38-I38)) -> N/A | O38: =IF(OR(N38="Fail",L38="",L38>TODAY()),"N/A",IF(P38="",TODAY()-L38,P38-L38)) -> N/A | U38: =IF(OR(T38="Fail",P38="",P38>TODAY()),"N/A",IF(V38="",TODAY()-P38,V38-P38)) -> N/A | Y38: Recruiter Screen - Invited | Z38: Active
B39: =IF(C39="","","FDE-"&TEXT(ROW()-7,"000")) -> FDE-032 | C39: Bangalore Harish, Kushal | D39: Frontier GenAI | E39: Indeed | G39: Diana Gutman (diagutman@deloitte.com) | H39: =IF(OR(F39="",F39>TODAY()),"N/A",IF(I39="",TODAY()-F39,I39-F39)) -> N/A | J39: Pass | K39: =IF(OR(J39="Fail",I39="",I39>TODAY()),"N/A",IF(L39="",TODAY()-I39,L39-I39)) -> N/A | O39: =IF(OR(N39="Fail",L39="",L39>TODAY()),"N/A",IF(P39="",TODAY()-L39,P39-L39)) -> N/A | U39: =IF(OR(T39="Fail",P39="",P39>TODAY()),"N/A",IF(V39="",TODAY()-P39,V39-P39)) -> N/A | Y39: Recruiter Screen - Being Scheduled | Z39: Active
B40: =IF(C40="","","FDE-"&TEXT(ROW()-7,"000")) -> FDE-033 | C40: Butler, Miles | D40: Frontier GenAI | E40: Agency Referral | G40: Diana Gutman (diagutman@deloitte.com) | H40: =IF(OR(F40="",F40>TODAY()),"N/A",IF(I40="",TODAY()-F40,I40-F40)) -> N/A | J40: Pass | K40: =IF(OR(J40="Fail",I40="",I40>TODAY()),"N/A",IF(L40="",TODAY()-I40,L40-I40)) -> N/A | O40: =IF(OR(N40="Fail",L40="",L40>TODAY()),"N/A",IF(P40="",TODAY()-L40,P40-L40)) -> N/A | U40: =IF(OR(T40="Fail",P40="",P40>TODAY()),"N/A",IF(V40="",TODAY()-P40,V40-P40)) -> N/A | Y40: Round 1 - Invite | Z40: Active
B41: =IF(C41="","","FDE-"&TEXT(ROW()-7,"000")) -> FDE-034 | C41: Chavan, Prajakta | D41: Palantir | E41: Employee Referral | G41: Paul Lemmon (plemmon@deloitte.com) | H41: =IF(OR(F41="",F41>TODAY()),"N/A",IF(I41="",TODAY()-F41,I41-F41)) -> N/A | J41: Pass | K41: =IF(OR(J41="Fail",I41="",I41>TODAY()),"N/A",IF(L41="",TODAY()-I41,L41-I41)) -> N/A | O41: =IF(OR(N41="Fail",L41="",L41>TODAY()),"N/A",IF(P41="",TODAY()-L41,P41-L41)) -> N/A | U41: =IF(OR(T41="Fail",P41="",P41>TODAY()),"N/A",IF(V41="",TODAY()-P41,V41-P41)) -> N/A | Y41: Recruiter Screen - Invited | Z41: Active
B42: =IF(C42="","","FDE-"&TEXT(ROW()-7,"000")) -> FDE-035 | C42: Chintakunta, Namatha | D42: Frontier GenAI | E42: LinkedIn | G42: Diana Gutman (diagutman@deloitte.com) | H42: =IF(OR(F42="",F42>TODAY()),"N/A",IF(I42="",TODAY()-F42,I42-F42)) -> N/A | J42: Pass | K42: =IF(OR(J42="Fail",I42="",I42>TODAY()),"N/A",IF(L42="",TODAY()-I42,L42-I42)) -> N/A | O42: =IF(OR(N42="Fail",L42="",L42>TODAY()),"N/A",IF(P42="",TODAY()-L42,P42-L42)) -> N/A | U42: =IF(OR(T42="Fail",P42="",P42>TODAY()),"N/A",IF(V42="",TODAY()-P42,V42-P42)) -> N/A | Y42: Recruiter Screen - Invited | Z42: Active
B43: =IF(C43="","","FDE-"&TEXT(ROW()-7,"000")) -> FDE-036 | C43: Cp, Rudrama | D43: Palantir | E43: Deloitte US Careers | G43: Paul Lemmon (plemmon@deloitte.com) | H43: =IF(OR(F43="",F43>TODAY()),"N/A",IF(I43="",TODAY()-F43,I43-F43)) -> N/A | J43: Pass | K43: =IF(OR(J43="Fail",I43="",I43>TODAY()),"N/A",IF(L43="",TODAY()-I43,L43-I43)) -> N/A | O43: =IF(OR(N43="Fail",L43="",L43>TODAY()),"N/A",IF(P43="",TODAY()-L43,P43-L43)) -> N/A | U43: =IF(OR(T43="Fail",P43="",P43>TODAY()),"N/A",IF(V43="",TODAY()-P43,V43-P43)) -> N/A | Y43: Round 1 - Invite | Z43: Active
B44: =IF(C44="","","FDE-"&TEXT(ROW()-7,"000")) -> FDE-037 | C44: Dubey, Shivam | D44: Databricks | E44: Employee Referral | G44: Diana Gutman (diagutman@deloitte.com) | H44: =IF(OR(F44="",F44>TODAY()),"N/A",IF(I44="",TODAY()-F44,I44-F44)) -> N/A | J44: Pass | K44: =IF(OR(J44="Fail",I44="",I44>TODAY()),"N/A",IF(L44="",TODAY()-I44,L44-I44)) -> N/A | O44: =IF(OR(N44="Fail",L44="",L44>TODAY()),"N/A",IF(P44="",TODAY()-L44,P44-L44)) -> N/A | U44: =IF(OR(T44="Fail",P44="",P44>TODAY()),"N/A",IF(V44="",TODAY()-P44,V44-P44)) -> N/A | Y44: Recruiter Screen - Invited | Z44: Active
... B72: =IF(C72="","","FDE-"&TEXT(ROW()-7,"000")) -> FDE-065 | C72: Vuyyuru, Bhavana Reddy | D72: Snowflake | E72: LinkedIn | G72: Paul Lemmon (plemmon@deloitte.com) | H72: =IF(OR(F72="",F72>TODAY()),"N/A",IF(I72="",TODAY()-F72,I72-F72)) -> N/A | J72: Pass | K72: =IF(OR(J72="Fail",I72="",I72>TODAY()),"N/A",IF(L72="",TODAY()-I72,L72-I72)) -> N/A | O72: =IF(OR(N72="Fail",L72="",L72>TODAY()),"N/A",IF(P72="",TODAY()-L72,P72-L72)) -> N/A | U72: =IF(OR(T72="Fail",P72="",P72>TODAY()),"N/A",IF(V72="",TODAY()-P72,V72-P72)) -> N/A | Y72: Recruiter Screen - Invited | Z72: Active
...

Sheet FDE Interviewers
A4: FDE Interviewers
A6: Round 1 – Behavioral Screening | B6: Round 2 – Panel Solution Review | C6: Round 3 – Final Interview | E6: Recruiting Management POC: @Goss, Angela, @Bennett, Jeffrey
A7: Initial 1:1 behavioral, followed by problem set up if candidate passes | B7: Panel review of candidate’s working software/agentic solution | C7: 1:1 with one of FDE Team leaders | F7: R1 Interview guidance: | G7: FDE Round 1 Interview Content
A8: Faruk Muratovic Akash Tayal Tim Juravich Prakul Sharma Jillian Wanner Baris Sarer Jon Smyrl Mike Schuler Phuong Lecong Roy Yang Frank Cantelmi Chris Carella Johnny Araujo | B8: One of the interviewers from Round 1 + one to two of the following (or their selected delegate): | C8: Faruk Muratovic Jason Wainstein Mark Urbanzyk Tim Juravich (or delegate) | F8: R2 Interview guidance: | G8: FDE Round 2 Interview Content
B9: Anthropic - Chris Carella - Prakul Sharma - Vinay Lekhraju - Jatin Dave - Ashish Chandra - Adrian Mendoza - Phuong Lecong
B10: Databricks - Mani Kandasamy - Brijraj Limbad - Joyce Snelders - Gayathri Ramaswami - Vinay Lekhraju
B11: Snowflake - Rupesh Dandekar - Mainak Sarkar
B12: AWS w/ its relevant AI Engineering Products - Tony Witherspoon - Phuong Lecong - Mike Schuler
B13: Google w/ its relevant AI Enterprise Products - Mamoun Hirzalla - Renuka Balasubramaniam - Sandeep Arora - David Zhu
B14: OpenAI - Niraj Juneja - Manoj Suvaran
B15: Microsoft w/ its relevant AI Enterprise Products: - Scott Rodgers - Tyson Thedinger
B16: Salesforce - Matt Fisher - Yash Agarwal
B17: ServiceNow - Matt Edward Ku - Krishnakant Dave
B18: Other platforms ramping up and respective CTOs will be part of and recommend interview panelists

Sheet Interviewer Capacity
B4: Interviewer Capacity Inputs
B5: Edit the yellow cells. These drive the capacity warnings and load metrics on the Dashboard. Update weekly as the interviewer pool grows or shrinks.
B7: ROUND-LEVEL CAPACITY
B8: Round | C8: # of Interviewers Available | D8: Interviews per Interviewer per Week (capacity) | E8: Weekly Capacity (auto) | F8: Target Throughput (candidates/week) | G8: Utilization at Target (auto) | H8: Notes
B9: Recruiter Screen | C9: 2 | D9: 20 | E9: =C9*D9 -> 40 | F9: 40 | G9: =IFERROR(F9/E9,0) -> 1 | H9: Recruiters + sourcers. Bottleneck during TAM freeze.
B10: Round 1 — 30 minute 1:1 Behavioral Screening. If candidate passes, then given a take home assignment to prepare for the next interview. | C10: 13 | D10: 2 | E10: =C10*D10 -> 26 | F10: 20 | G10: =IFERROR(F10/E10,0) -> 0.76923077 | H10: FDE Academy instructor or grad.
B11: Round 2 — Panel Interview Review the solution the candidate has built, test their approach and problem solving skills, and very importantly understand their technical abilities on a specific platform. Panel consists of minimum of two and up to three members for this second interview: 1) Original interviewer from behavioral screening or another PMD/SM interviewer 2) Platform CTO or another platform specific PMD/SM SME (e.g. Databricks Engineer for Databricks FDE candidate or Anthropic/Claude proficient AI Engineer for Frontier AI FDE candidate) 3) Domain specialist (e.g. life sciences sector specialist, supply chain SME… if relevant) | C11: 29 | D11: 1 | E11: =C11*D11 -> 29 | F11: 8 | G11: =IFERROR(F11/E11,0) -> 0.27586207 | H11: Needs FDE practitioner + OP practitioner + optional PPMD per panel.
B12: Round 3 — Final 1:1 Interview With Senior FDE Leader to confirm ability to shape, sell, and deliver, and overall fit. | C12: 4 | D12: 2 | E12: =C12*D12 -> 8 | F12: 4 | G12: =IFERROR(F12/E12,0) -> 0.5 | H12: Faruk M., Tim Juravich, Urbanzyk, Jason Wainstein.
B15: DOMAIN SPECIALIST COVERAGE BY PLATFORM
B16: Domain specialists are pulled into Round 2 panels. If a platform has only 1 specialist and several candidates in flight, scheduling will stall.
B17: Platform | C17: # Domain Specialists | D17: Active Candidates (auto) | E17: Candidates per Specialist (auto) | F17: Risk Flag (auto)
B18: Databricks | C18: 5 | D18: =COUNTIFS('Candidate Tracker'!$D$8:$D$256,B18,'Candidate Tracker'!$Z$8:$Z$256,"Active") -> 15 | E18: =IFERROR(D18/C18,0) -> 3 | F18: =IF(C18=0,"No specialist",IF(E18>=3,"⚠ HIGH",IF(E18>=1.5,"Medium","OK"))) -> ⚠ HIGH
B19: Palantir | C19: 0 | D19: =COUNTIFS('Candidate Tracker'!$D$8:$D$256,B19,'Candidate Tracker'!$Z$8:$Z$256,"Active") -> 10 | E19: =IFERROR(D19/C19,0) -> 0 | F19: =IF(C19=0,"No specialist",IF(E19>=3,"⚠ HIGH",IF(E19>=1.5,"Medium","OK"))) -> No specialist
B20: AWS | C20: 3 | D20: =COUNTIFS('Candidate Tracker'!$D$8:$D$256,B20,'Candidate Tracker'!$Z$8:$Z$256,"Active") -> 16 | E20: =IFERROR(D20/C20,0) -> 5.3333333 | F20: =IF(C20=0,"No specialist",IF(E20>=3,"⚠ HIGH",IF(E20>=1.5,"Medium","OK"))) -> ⚠ HIGH
B21: Anthropic | C21: 7 | D21: =COUNTIFS('Candidate Tracker'!$D$8:$D$256,B21,'Candidate Tracker'!$Z$8:$Z$256,"Active") -> 0 | E21: =IFERROR(D21/C21,0) -> 0 | F21: =IF(C21=0,"No specialist",IF(E21>=3,"⚠ HIGH",IF(E21>=1.5,"Medium","OK"))) -> OK
B22: Google | C22: 4 | D22: =COUNTIFS('Candidate Tracker'!$D$8:$D$256,B22,'Candidate Tracker'!$Z$8:$Z$256,"Active") -> 0 | E22: =IFERROR(D22/C22,0) -> 0 | F22: =IF(C22=0,"No specialist",IF(E22>=3,"⚠ HIGH",IF(E22>=1.5,"Medium","OK"))) -> OK
B23: OpenAI | C23: 2 | D23: =COUNTIFS('Candidate Tracker'!$D$8:$D$256,B23,'Candidate Tracker'!$Z$8:$Z$256,"Active") -> 0 | E23: =IFERROR(D23/C23,0) -> 0 | F23: =IF(C23=0,"No specialist",IF(E23>=3,"⚠ HIGH",IF(E23>=1.5,"Medium","OK"))) -> OK
B24: Microsoft | C24: 2 | D24: =COUNTIFS('Candidate Tracker'!$D$8:$D$256,B24,'Candidate Tracker'!$Z$8:$Z$256,"Active") -> 0 | E24: =IFERROR(D24/C24,0) -> 0 | F24: =IF(C24=0,"No specialist",IF(E24>=3,"⚠ HIGH",IF(E24>=1.5,"Medium","OK"))) -> OK
B25: Snowflake | C25: 2 | D25: =COUNTIFS('Candidate Tracker'!$D$8:$D$256,B25,'Candidate Tracker'!$Z$8:$Z$256,"Active") -> 9 | E25: =IFERROR(D25/C25,0) -> 4.5 | F25: =IF(C25=0,"No specialist",IF(E25>=3,"⚠ HIGH",IF(E25>=1.5,"Medium","OK"))) -> ⚠ HIGH
B26: NVIDIA | C26: 0 | D26: =COUNTIFS('Candidate Tracker'!$D$8:$D$256,B26,'Candidate Tracker'!$Z$8:$Z$256,"Active") -> 0 | E26: =IFERROR(D26/C26,0) -> 0 | F26: =IF(C26=0,"No specialist",IF(E26>=3,"⚠ HIGH",IF(E26>=1.5,"Medium","OK"))) -> No specialist
B27: Oracle | C27: 0 | D27: =COUNTIFS('Candidate Tracker'!$D$8:$D$256,B27,'Candidate Tracker'!$Z$8:$Z$256,"Active") -> 0 | E27: =IFERROR(D27/C27,0) -> 0 | F27: =IF(C27=0,"No specialist",IF(E27>=3,"⚠ HIGH",IF(E27>=1.5,"Medium","OK"))) -> No specialist
B28: SAP | C28: 0 | D28: =COUNTIFS('Candidate Tracker'!$D$8:$D$256,B28,'Candidate Tracker'!$Z$8:$Z$256,"Active") -> 0 | E28: =IFERROR(D28/C28,0) -> 0 | F28: =IF(C28=0,"No specialist",IF(E28>=3,"⚠ HIGH",IF(E28>=1.5,"Medium","OK"))) -> No specialist
B29: Salesforce | C29: 2 | D29: =COUNTIFS('Candidate Tracker'!$D$8:$D$256,B29,'Candidate Tracker'!$Z$8:$Z$256,"Active") -> 0 | E29: =IFERROR(D29/C29,0) -> 0 | F29: =IF(C29=0,"No specialist",IF(E29>=3,"⚠ HIGH",IF(E29>=1.5,"Medium","OK"))) -> OK
... B31: Workday | C31: 0 | D31: =COUNTIFS('Candidate Tracker'!$D$8:$D$256,B31,'Candidate Tracker'!$Z$8:$Z$256,"Active") -> 0 | E31: =IFERROR(D31/C31,0) -> 0 | F31: =IF(C31=0,"No specialist",IF(E31>=3,"⚠ HIGH",IF(E31>=1.5,"Medium","OK"))) -> No specialist

Sheet Lookups
B4: Lookup Lists
B6: Platforms | C6: Current Stage | D6: Status | E6: Outcome | F6: Source | H6: Note: This sheet feeds dropdown lists in the Candidate Tracker. Add new platforms or statuses here and they'll appear as options in the tracker.
B7: Databricks | C7: Applicant | D7: Active | E7: Pending | F7: LinkedIn
B8: Palantir | C8: Recruiter Screen - Being Scheduled | D8: On Hold | E8: Pass | F8: Referral
B9: AWS | C9: Recruiter Screen - Invited | D9: Rejected | E9: Fail | F9: TAM/Workday
B10: Anthropic | C10: Recruiter Screen - Conducted | D10: Withdrew | E10: Strong Hire | F10: Recruiter Outreach
B11: Google | C11: Round 1 - Invite | D11: Hired | E11: Hire | F11: Job Board
B12: OpenAI | C12: Round 1 - Conducted | E12: No Hire | F12: Career Fair
B13: Microsoft | C13: Round 2 - Invite | E13: N/A | F13: Internal Transfer
B14: Snowflake | C14: Round 2 - Conducted | F14: Other
B15: Alphabet | C15: Round 3 - Invite
B16: NVIDIA | C16: Round 3 - Conducted
B17: Oracle | C17: Offer Extended
B18: SAP | C18: Hired and Ready to Onboard
B19: Salesforce | C19: Rejected
B20: ServiceNow | C20: Withdrew
B21: Workday | C21: On Hold
B22: Cyber
B23: S&T
B24: HC
B25: EP
B26: Other
B27: Frontier GenAI
